{"trial_id": "0001", "hyperparameters": {"space": [{"class_name": "Choice", "config": {"name": "activation", "default": "relu", "conditions": [], "values": ["relu", "tanh"], "ordered": false}}, {"class_name": "Int", "config": {"name": "first_units", "default": null, "conditions": [], "min_value": 1, "max_value": 30, "step": 5, "sampling": "linear"}}, {"class_name": "Int", "config": {"name": "num_layers", "default": null, "conditions": [], "min_value": 1, "max_value": 5, "step": 1, "sampling": "linear"}}, {"class_name": "Int", "config": {"name": "units_0", "default": null, "conditions": [], "min_value": 1, "max_value": 30, "step": 5, "sampling": "linear"}}, {"class_name": "Int", "config": {"name": "units_1", "default": null, "conditions": [], "min_value": 1, "max_value": 30, "step": 5, "sampling": "linear"}}, {"class_name": "Int", "config": {"name": "units_2", "default": null, "conditions": [], "min_value": 1, "max_value": 30, "step": 5, "sampling": "linear"}}], "values": {"activation": "relu", "first_units": 26, "num_layers": 1, "units_0": 26, "units_1": 11, "units_2": 6, "tuner/epochs": 3, "tuner/initial_epoch": 0, "tuner/bracket": 2, "tuner/round": 0}}, "metrics": {"metrics": {}}, "score": null, "best_step": 0, "status": "FAILED", "message": "Traceback (most recent call last):\n  File \"C:\\Users\\nycdoe\\anaconda3\\Lib\\site-packages\\keras_tuner\\src\\engine\\base_tuner.py\", line 274, in _try_run_and_update_trial\n    self._run_and_update_trial(trial, *fit_args, **fit_kwargs)\n  File \"C:\\Users\\nycdoe\\anaconda3\\Lib\\site-packages\\keras_tuner\\src\\engine\\base_tuner.py\", line 239, in _run_and_update_trial\n    results = self.run_trial(trial, *fit_args, **fit_kwargs)\n              ^^^^^^^^^^^^^^^^^^^^^^^^^^^^^^^^^^^^^^^^^^^^^^\n  File \"C:\\Users\\nycdoe\\anaconda3\\Lib\\site-packages\\keras_tuner\\src\\tuners\\hyperband.py\", line 427, in run_trial\n    return super().run_trial(trial, *fit_args, **fit_kwargs)\n           ^^^^^^^^^^^^^^^^^^^^^^^^^^^^^^^^^^^^^^^^^^^^^^^^^\n  File \"C:\\Users\\nycdoe\\anaconda3\\Lib\\site-packages\\keras_tuner\\src\\engine\\tuner.py\", line 314, in run_trial\n    obj_value = self._build_and_fit_model(trial, *args, **copied_kwargs)\n                ^^^^^^^^^^^^^^^^^^^^^^^^^^^^^^^^^^^^^^^^^^^^^^^^^^^^^^^^\n  File \"C:\\Users\\nycdoe\\anaconda3\\Lib\\site-packages\\keras_tuner\\src\\engine\\tuner.py\", line 233, in _build_and_fit_model\n    results = self.hypermodel.fit(hp, model, *args, **kwargs)\n              ^^^^^^^^^^^^^^^^^^^^^^^^^^^^^^^^^^^^^^^^^^^^^^^\n  File \"C:\\Users\\nycdoe\\anaconda3\\Lib\\site-packages\\keras_tuner\\src\\engine\\hypermodel.py\", line 149, in fit\n    return model.fit(*args, **kwargs)\n           ^^^^^^^^^^^^^^^^^^^^^^^^^^\n  File \"C:\\Users\\nycdoe\\anaconda3\\Lib\\site-packages\\keras\\src\\utils\\traceback_utils.py\", line 122, in error_handler\n    raise e.with_traceback(filtered_tb) from None\n  File \"C:\\Users\\nycdoe\\anaconda3\\Lib\\site-packages\\keras\\src\\layers\\input_spec.py\", line 227, in assert_input_compatibility\n    raise ValueError(\nValueError: Exception encountered when calling Sequential.call().\n\n\u001b[1mInput 0 of layer \"dense\" is incompatible with the layer: expected axis -1 of input shape to have value 2, but received input with shape (None, 43)\u001b[0m\n\nArguments received by Sequential.call():\n  \u2022 inputs=tf.Tensor(shape=(None, 43), dtype=float32)\n  \u2022 training=True\n  \u2022 mask=None\n"}